<?xml version="1.0" encoding="utf-8"?>
<!-- =================================================================================== -->
<!-- |    This document was autogenerated by xacro from spring.urdf.xacro              | -->
<!-- |    EDITING THIS FILE BY HAND IS NOT RECOMMENDED                                 | -->
<!-- =================================================================================== -->
<!--Description: this is a simple chain robot whose natural pose is a chain along the y axis-->
<!--Note: Each link should have the contact block, and the recommended values from Erwin Counmans, the PyBullet Creator, stiffness=30000 and damping=1000   -->
<robot name="diff_drive">
  <link name="base_link">
    <visual>
      <origin rpy="0 0 0" xyz="0.05 0 0"/>
      <geometry>
        <box size="0.1 0.1 0.1"/>
      </geometry>
      <material name="arm_yellow_mat">
        <color rgba="1 1 0 1.0"/>
      </material>
    </visual>
    <inertial>
      <mass value="1.0"/>
      <inertia ixx="0.0016666" ixy="0.0" ixz="0.0" iyy="0.0016666" iyz="0.0" izz="0.0016666"/>
    </inertial>
    <collision>
      <origin rpy="0 0 0" xyz="0.05 0 0"/>
      <geometry>
        <box size="0.1 0.1 0.1"/>
      </geometry>
    </collision>
    <contact>
      <rolling_friction value="0.0"/>
      <spinning_friction value="0.0"/>
      <stiffness value="30000.0"/>
      <damping value="1000.0"/>
      <lateral_friction value="0.0"/>
    </contact>
  </link>
  <joint name="base_link_arm1" type="fixed">
    <origin rpy="0.0 0.0 0.0" xyz="0.1 0 0"/>
    <parent link="base_link"/>
    <child link="arm1"/>
    <dynamics damping="0.0" friction="0.0"/>
    <limit effort="10000" lower="1000" upper="-1000" velocity="10000"/>
  </joint>
  <link name="arm1">
    <visual>
      <origin rpy="0 0 0" xyz="0.5 0 0"/>
      <geometry>
        <box size="1.0 0.1 0.1"/>
      </geometry>
      <material name="arm_pink_mat">
        <color rgba="1.0 0.42 0.72 1.0"/>
      </material>
    </visual>
    <inertial>
      <mass value="0.00001"/>
      <inertia ixx="0.000000002" ixy="0.0" ixz="0.0" iyy="0.000000084" iyz="0.0" izz="0.000000084"/>
    </inertial>
    <collision>
      <origin rpy="0 0 0" xyz="0.5 0 0"/>
      <geometry>
        <box size="1.0 0.1 0.1"/>
      </geometry>
    </collision>
    <contact>
      <rolling_friction value="0.0"/>
      <spinning_friction value="0.0"/>
      <stiffness value="30000.0"/>
      <damping value="1000.0"/>
      <lateral_friction value="0.0"/>
    </contact>
  </link>
  <joint name="spring_joint" type="continuous">
    <origin rpy="0.0 0.0 0.0" xyz="1.0 0 0"/>
    <parent link="arm1"/>
    <child link="arm2"/>
    <dynamics damping="0.0" friction="0.0"/>
    <limit effort="10000" lower="1000" upper="-1000" velocity="10000"/>
    <axis xyz="0 0 1"/>
  </joint>
  <link name="arm2">
    <visual>
      <origin rpy="0 0 0" xyz="0.5 0 0"/>
      <geometry>
        <box size="1.0 0.1 0.1"/>
      </geometry>
      <material name="arm_pink_mat">
        <color rgba="1.0 0.42 0.72 1.0"/>
      </material>
    </visual>
    <inertial>
      <mass value="0.00001"/>
      <inertia ixx="0.000000002" ixy="0.0" ixz="0.0" iyy="0.000000084" iyz="0.0" izz="0.000000084"/>
    </inertial>
    <collision>
      <origin rpy="0 0 0" xyz="0.5 0 0"/>
      <geometry>
        <box size="1.0 0.1 0.1"/>
      </geometry>
    </collision>
    <contact>
      <rolling_friction value="0.0"/>
      <spinning_friction value="0.0"/>
      <stiffness value="30000.0"/>
      <damping value="1000.0"/>
      <lateral_friction value="0.0"/>
    </contact>
  </link>
  <joint name="arm2_end_effector" type="fixed">
    <origin rpy="0.0 0.0 0.0" xyz="1.0 0 0"/>
    <parent link="arm2"/>
    <child link="end_effector"/>
    <dynamics damping="0.0" friction="0.0"/>
    <limit effort="10000" lower="1000" upper="-1000" velocity="10000"/>
  </joint>
  <link name="end_effector">
    <visual>
      <origin rpy="0 0 0" xyz="0.05 0 0"/>
      <geometry>
        <box size="0.1 0.1 0.1"/>
      </geometry>
      <material name="arm_yellow_mat">
        <color rgba="1 1 0 1.0"/>
      </material>
    </visual>
    <inertial>
      <mass value="1.0"/>
      <inertia ixx="0.0016666" ixy="0.0" ixz="0.0" iyy="0.0016666" iyz="0.0" izz="0.0016666"/>
    </inertial>
    <collision>
      <origin rpy="0 0 0" xyz="0.05 0 0"/>
      <geometry>
        <box size="0.1 0.1 0.1"/>
      </geometry>
    </collision>
    <contact>
      <rolling_friction value="0.0"/>
      <spinning_friction value="0.0"/>
      <stiffness value="30000.0"/>
      <damping value="1000.0"/>
      <lateral_friction value="0.0"/>
    </contact>
  </link>
</robot>

