<?xml version="1.0" encoding="utf-8"?>
<!-- =================================================================================== -->
<!-- |    This document was autogenerated by xacro from delta_robot.urdf.xacro         | -->
<!-- |    EDITING THIS FILE BY HAND IS NOT RECOMMENDED                                 | -->
<!-- =================================================================================== -->
<robot name="delta-robot-RUU">
  <!-- These parameters are stored in parameters.h and are passed in
       by calling delta_parameters at the commandline when generated the
       urdf from this xacro file, via arg:=value 

Note that since this is a parallel robot it can't fully be captured by a urdf
Instead, the user must make sure the loop closure constraints are satisfied.

TODO: not all the properties are in the c header file yet and the command
line program has not been written
-->
  <!-- define colors -->
  <material name="base_color">
    <color rgba="0.1 0.2 0.2 1.0"/>
  </material>
  <material name="platform_color">
    <color rgba="0.0 0.0 0.0 1.0"/>
  </material>
  <material name="lower_leg_color">
    <color rgba="0.0 0.0 0.6 1.0"/>
  </material>
  <material name="upper_leg_color">
    <color rgba="0.0 0.6 0.0 1.0"/>
  </material>
  <material name="prespring_color">
    <color rgba="0.6 0.6 0.6 1.0"/>
  </material>
  <material name="heart_pink">
    <color rgba="1.0 0.76 0.80 1.0"/>
  </material>
  <material name="dark_pink">
    <color rgba="1.0 0.43 0.51 1.0"/>
  </material>
  <material name="light_pink">
    <color rgba="0.94 0.50 0.50 1.0"/>
  </material>
  <link name="base_link">
    <visual>
      <!-- shift the visual so that the link frame is at one end of the cylinder, and
           rotate it so that it matches the proper axis alignment -->
      <origin rpy="0 0 0" xyz="0 0 0.0047625"/>
      <geometry>
        <cylinder length="0.009525" radius="0.18"/>
      </geometry>
      <material name="heart_pink"/>
    </visual>
    <!--    <origin xyz="${0 if axis == 'z' else h/2.0} 0 ${h/2.0 if axis == 'z' else 0}" rpy="0 ${0 if axis == 'z' else -pi/2.0} 0" />-->
    <inertial>
      <mass value="2.5"/>
      <!-- shift the origin to the center of the link from the end. how this is done depends on if
      the cylinder is x aligned or z aligned-->
      <origin rpy="0 0 0" xyz="0 0 0.0047625"/>
      <inertia ixx="0.0202689011719" ixy="0" ixz="0" iyy="0.0202689011719" iyz="0" izz="0.0405"/>
    </inertial>
    <collision>
      <origin rpy="0 -1.57079632679 0" xyz="0.0047625 0 0"/>
      <geometry>
        <cylinder length="0.009525" radius="0.18"/>
      </geometry>
    </collision>
  </link>
  <link name="world">
    <visual>
      <!-- shift the visual so that the link frame is at one end of the cylinder, and
           rotate it so that it matches the proper axis alignment -->
      <origin rpy="0 -1.57079632679 0" xyz="5e-06 0 0"/>
      <geometry>
        <cylinder length="1e-05" radius="1e-05"/>
      </geometry>
      <material name="base_color"/>
    </visual>
    <!--    <origin xyz="${0 if axis == 'z' else h/2.0} 0 ${h/2.0 if axis == 'z' else 0}" rpy="0 ${0 if axis == 'z' else -pi/2.0} 0" />-->
    <inertial>
      <mass value="1e-05"/>
      <!-- shift the origin to the center of the link from the end. how this is done depends on if
      the cylinder is x aligned or z aligned-->
      <origin rpy="0 0 0" xyz="5e-06 0 0"/>
      <inertia ixx="5e-16" ixy="0" ixz="0" iyy="3.33333333333e-16" iyz="0" izz="3.33333333333e-16"/>
    </inertial>
    <collision>
      <origin rpy="0 -1.57079632679 0" xyz="5e-06 0 0"/>
      <geometry>
        <cylinder length="1e-05" radius="1e-05"/>
      </geometry>
    </collision>
  </link>
  <!-- connect the base to the world -->
  <joint name="fixed" type="fixed">
    <parent link="world"/>
    <origin xyz="0 0 -0.046375"/>
    <child link="base_link"/>
  </joint>
  <link name="platform_link">
    <visual>
      <!-- shift the visual so that the link frame is at one end of the cylinder, and
           rotate it so that it matches the proper axis alignment -->
      <origin rpy="0 0 0" xyz="0 0 0.005"/>
      <geometry>
        <cylinder length="0.01" radius="0.062"/>
      </geometry>
      <material name="heart_pink"/>
    </visual>
    <!--    <origin xyz="${0 if axis == 'z' else h/2.0} 0 ${h/2.0 if axis == 'z' else 0}" rpy="0 ${0 if axis == 'z' else -pi/2.0} 0" />-->
    <inertial>
      <mass value="0.5"/>
      <!-- shift the origin to the center of the link from the end. how this is done depends on if
      the cylinder is x aligned or z aligned-->
      <origin rpy="0 0 0" xyz="0 0 0.005"/>
      <inertia ixx="0.000484666666667" ixy="0" ixz="0" iyy="0.000484666666667" iyz="0" izz="0.000961"/>
    </inertial>
    <collision>
      <origin rpy="0 -1.57079632679 0" xyz="0.005 0 0"/>
      <geometry>
        <cylinder length="0.01" radius="0.062"/>
      </geometry>
    </collision>
  </link>
  <!-- The x,y,z position of the platform is handled by a chain of 3 prismatic joints -->
  <!-- handle the x motion of the platform -->
  <link name="platform_x_link">
    <!--    <origin xyz="${0 if axis == 'z' else h/2.0} 0 ${h/2.0 if axis == 'z' else 0}" rpy="0 ${0 if axis == 'z' else -pi/2.0} 0" />-->
    <inertial>
      <mass value="1e-05"/>
      <!-- shift the origin to the center of the link from the end. how this is done depends on if
      the cylinder is x aligned or z aligned-->
      <origin rpy="0 0 0" xyz="5e-11 0 0"/>
      <inertia ixx="5e-26" ixy="0" ixz="0" iyy="3.33333333333e-26" iyz="0" izz="3.33333333333e-26"/>
    </inertial>
  </link>
  <joint name="x" type="prismatic">
    <parent link="world"/>
    <child link="platform_x_link"/>
    <axis xyz="1 0 0"/>
    <!-- Limits are required but currently arbitrary -->
    <limit effort="100" lower="-0.748" upper="0.748" velocity="100"/>
    <dynamics damping="0.0" friction="0.0"/>
  </joint>
  <!-- handle the y motion of the platform -->
  <link name="platform_y_link">
    <!--    <origin xyz="${0 if axis == 'z' else h/2.0} 0 ${h/2.0 if axis == 'z' else 0}" rpy="0 ${0 if axis == 'z' else -pi/2.0} 0" />-->
    <inertial>
      <mass value="1e-05"/>
      <!-- shift the origin to the center of the link from the end. how this is done depends on if
      the cylinder is x aligned or z aligned-->
      <origin rpy="0 0 0" xyz="5e-11 0 0"/>
      <inertia ixx="5e-26" ixy="0" ixz="0" iyy="3.33333333333e-26" iyz="0" izz="3.33333333333e-26"/>
    </inertial>
  </link>
  <joint name="y" type="prismatic">
    <parent link="platform_x_link"/>
    <child link="platform_y_link"/>
    <axis xyz="0 1 0"/>
    <!-- Limits are required but currently arbitrary -->
    <limit effort="100" lower="-0.748" upper="0.748" velocity="100"/>
    <dynamics damping="0.0" friction="0.0"/>
  </joint>
  <!-- handle the z motion of the platform -->
  <joint name="z" type="prismatic">
    <parent link="platform_y_link"/>
    <child link="platform_link"/>
    <axis xyz="0 0 1"/>
    <!-- Limits are required but currently arbitrary -->
    <limit effort="100" lower="-0.046375" upper="0.568" velocity="100"/>
    <dynamics damping="0.0" friction="0.0"/>
  </joint>
  <!-- This link and fixed joint is used as a placeholder for where the lower leg attaches to the base -->
  <link name="lower_leg_attach_link_1">
    <!--    <origin xyz="${0 if axis == 'z' else h/2.0} 0 ${h/2.0 if axis == 'z' else 0}" rpy="0 ${0 if axis == 'z' else -pi/2.0} 0" />-->
    <inertial>
      <mass value="1e-05"/>
      <!-- shift the origin to the center of the link from the end. how this is done depends on if
      the cylinder is x aligned or z aligned-->
      <origin rpy="0 0 0" xyz="5e-11 0 0"/>
      <inertia ixx="5e-26" ixy="0" ixz="0" iyy="3.33333333333e-26" iyz="0" izz="3.33333333333e-26"/>
    </inertial>
  </link>
  <joint name="lower_leg_attach_joint_1" type="fixed">
    <parent link="world"/>
    <child link="lower_leg_attach_link_1"/>
    <origin rpy="0 0 0" xyz="0.18 0.0 0"/>
    <dynamics damping="0.0" friction="0.0"/>
  </joint>
  <link name="lower_leg_1">
    <visual>
      <!-- shift the visual so that the link frame is at one end of the cylinder, and
           rotate it so that it matches the proper axis alignment -->
      <origin rpy="0 -1.57079632679 0" xyz="0.1 0 0"/>
      <geometry>
        <cylinder length="0.2" radius="0.009"/>
      </geometry>
      <material name="light_pink"/>
    </visual>
    <!--    <origin xyz="${0 if axis == 'z' else h/2.0} 0 ${h/2.0 if axis == 'z' else 0}" rpy="0 ${0 if axis == 'z' else -pi/2.0} 0" />-->
    <inertial>
      <mass value="1"/>
      <!-- shift the origin to the center of the link from the end. how this is done depends on if
      the cylinder is x aligned or z aligned-->
      <origin rpy="0 0 0" xyz="0.1 0 0"/>
      <inertia ixx="4.05e-05" ixy="0" ixz="0" iyy="0.00335358333333" iyz="0" izz="0.00335358333333"/>
    </inertial>
    <collision>
      <origin rpy="0 -1.57079632679 0" xyz="0.1 0 0"/>
      <geometry>
        <cylinder length="0.2" radius="0.009"/>
      </geometry>
    </collision>
  </link>
  <!-- connect the lower leg to the base -->
  <!-- this is the after the spring angle joint -->
  <joint name="theta_1" type="revolute">
    <parent link="lower_leg_attach_link_1"/>
    <child link="lower_leg_1"/>
    <origin rpy="0 0 0" xyz="0 0 0"/>
    <axis rpy="0 0 0" xyz="0 -1 0"/>
    <limit effort="100" lower="-0.785398163397" upper="1.57079632679" velocity="100"/>
    <dynamics damping="0.0" friction="0.0"/>
  </joint>
  <link name="lower_leg_prespring_1">
    <visual>
      <!-- shift the visual so that the link frame is at one end of the cylinder, and
           rotate it so that it matches the proper axis alignment -->
      <origin rpy="0 -1.57079632679 0" xyz="0.005 0 0"/>
      <geometry>
        <cylinder length="0.01" radius="0.02"/>
      </geometry>
      <material name="prespring_color"/>
    </visual>
    <!--    <origin xyz="${0 if axis == 'z' else h/2.0} 0 ${h/2.0 if axis == 'z' else 0}" rpy="0 ${0 if axis == 'z' else -pi/2.0} 0" />-->
    <inertial>
      <mass value="1"/>
      <!-- shift the origin to the center of the link from the end. how this is done depends on if
      the cylinder is x aligned or z aligned-->
      <origin rpy="0 0 0" xyz="0.005 0 0"/>
      <inertia ixx="0.0002" ixy="0" ixz="0" iyy="0.000108333333333" iyz="0" izz="0.000108333333333"/>
    </inertial>
    <collision>
      <origin rpy="0 -1.57079632679 0" xyz="0.005 0 0"/>
      <geometry>
        <cylinder length="0.01" radius="0.02"/>
      </geometry>
    </collision>
  </link>
  <joint name="phi_1" type="continuous">
    <parent link="lower_leg_attach_link_1"/>
    <child link="lower_leg_prespring_1"/>
    <origin rpy="0 0 1.57079632679" xyz="0 -0.09 0"/>
    <axis rpy="0 0 0" xyz="-1 0 0"/>
    <dynamics damping="0.0" friction="0.0"/>
  </joint>
  <!-- define a frame at the knee between the lower and upper legs -->
  <link name="knee_1">
    <!--    <origin xyz="${0 if axis == 'z' else h/2.0} 0 ${h/2.0 if axis == 'z' else 0}" rpy="0 ${0 if axis == 'z' else -pi/2.0} 0" />-->
    <inertial>
      <mass value="1e-05"/>
      <!-- shift the origin to the center of the link from the end. how this is done depends on if
      the cylinder is x aligned or z aligned-->
      <origin rpy="0 0 0" xyz="5e-11 0 0"/>
      <inertia ixx="5e-26" ixy="0" ixz="0" iyy="3.33333333333e-26" iyz="0" izz="3.33333333333e-26"/>
    </inertial>
  </link>
  <!-- define the universal joint between he upper and lower links -->
  <!-- This is the knee pitch angle joint -->
  <joint name="beta_1" type="continuous">
    <parent link="lower_leg_1"/>
    <child link="knee_1"/>
    <origin rpy="0 0 0" xyz="0.2 0 0"/>
    <axis rpy="0 0 0" xyz="0 -1 0"/>
    <dynamics damping="0.0" friction="0.0"/>
  </joint>
  <link name="upper_leg_1">
    <visual>
      <!-- shift the visual so that the link frame is at one end of the cylinder, and
           rotate it so that it matches the proper axis alignment -->
      <origin rpy="0 -1.57079632679 0" xyz="0.184 0 0"/>
      <geometry>
        <cylinder length="0.368" radius="0.009"/>
      </geometry>
      <material name="dark_pink"/>
    </visual>
    <!--    <origin xyz="${0 if axis == 'z' else h/2.0} 0 ${h/2.0 if axis == 'z' else 0}" rpy="0 ${0 if axis == 'z' else -pi/2.0} 0" />-->
    <inertial>
      <mass value="1"/>
      <!-- shift the origin to the center of the link from the end. how this is done depends on if
      the cylinder is x aligned or z aligned-->
      <origin rpy="0 0 0" xyz="0.184 0 0"/>
      <inertia ixx="4.05e-05" ixy="0" ixz="0" iyy="0.0113055833333" iyz="0" izz="0.0113055833333"/>
    </inertial>
    <collision>
      <origin rpy="0 -1.57079632679 0" xyz="0.184 0 0"/>
      <geometry>
        <cylinder length="0.368" radius="0.009"/>
      </geometry>
    </collision>
  </link>
  <!-- this is the knee yaw angle joint -->
  <joint name="gamma_1" type="continuous">
    <parent link="knee_1"/>
    <child link="upper_leg_1"/>
    <axis rpy="0 0 0" xyz="0 0 -1"/>
    <dynamics damping="0.0" friction="0.0"/>
  </joint>
  <!-- This link and fixed joint is used as a placeholder for where the lower leg attaches to the base -->
  <link name="lower_leg_attach_link_2">
    <!--    <origin xyz="${0 if axis == 'z' else h/2.0} 0 ${h/2.0 if axis == 'z' else 0}" rpy="0 ${0 if axis == 'z' else -pi/2.0} 0" />-->
    <inertial>
      <mass value="1e-05"/>
      <!-- shift the origin to the center of the link from the end. how this is done depends on if
      the cylinder is x aligned or z aligned-->
      <origin rpy="0 0 0" xyz="5e-11 0 0"/>
      <inertia ixx="5e-26" ixy="0" ixz="0" iyy="3.33333333333e-26" iyz="0" izz="3.33333333333e-26"/>
    </inertial>
  </link>
  <joint name="lower_leg_attach_joint_2" type="fixed">
    <parent link="world"/>
    <child link="lower_leg_attach_link_2"/>
    <origin rpy="0 0 2.09439510239" xyz="-0.09 0.155884572681 0"/>
    <dynamics damping="0.0" friction="0.0"/>
  </joint>
  <link name="lower_leg_2">
    <visual>
      <!-- shift the visual so that the link frame is at one end of the cylinder, and
           rotate it so that it matches the proper axis alignment -->
      <origin rpy="0 -1.57079632679 0" xyz="0.1 0 0"/>
      <geometry>
        <cylinder length="0.2" radius="0.009"/>
      </geometry>
      <material name="light_pink"/>
    </visual>
    <!--    <origin xyz="${0 if axis == 'z' else h/2.0} 0 ${h/2.0 if axis == 'z' else 0}" rpy="0 ${0 if axis == 'z' else -pi/2.0} 0" />-->
    <inertial>
      <mass value="1"/>
      <!-- shift the origin to the center of the link from the end. how this is done depends on if
      the cylinder is x aligned or z aligned-->
      <origin rpy="0 0 0" xyz="0.1 0 0"/>
      <inertia ixx="4.05e-05" ixy="0" ixz="0" iyy="0.00335358333333" iyz="0" izz="0.00335358333333"/>
    </inertial>
    <collision>
      <origin rpy="0 -1.57079632679 0" xyz="0.1 0 0"/>
      <geometry>
        <cylinder length="0.2" radius="0.009"/>
      </geometry>
    </collision>
  </link>
  <!-- connect the lower leg to the base -->
  <!-- this is the after the spring angle joint -->
  <joint name="theta_2" type="revolute">
    <parent link="lower_leg_attach_link_2"/>
    <child link="lower_leg_2"/>
    <origin rpy="0 0 0" xyz="0 0 0"/>
    <axis rpy="0 0 0" xyz="0 -1 0"/>
    <limit effort="100" lower="-0.785398163397" upper="1.57079632679" velocity="100"/>
    <dynamics damping="0.0" friction="0.0"/>
  </joint>
  <link name="lower_leg_prespring_2">
    <visual>
      <!-- shift the visual so that the link frame is at one end of the cylinder, and
           rotate it so that it matches the proper axis alignment -->
      <origin rpy="0 -1.57079632679 0" xyz="0.005 0 0"/>
      <geometry>
        <cylinder length="0.01" radius="0.02"/>
      </geometry>
      <material name="prespring_color"/>
    </visual>
    <!--    <origin xyz="${0 if axis == 'z' else h/2.0} 0 ${h/2.0 if axis == 'z' else 0}" rpy="0 ${0 if axis == 'z' else -pi/2.0} 0" />-->
    <inertial>
      <mass value="1"/>
      <!-- shift the origin to the center of the link from the end. how this is done depends on if
      the cylinder is x aligned or z aligned-->
      <origin rpy="0 0 0" xyz="0.005 0 0"/>
      <inertia ixx="0.0002" ixy="0" ixz="0" iyy="0.000108333333333" iyz="0" izz="0.000108333333333"/>
    </inertial>
    <collision>
      <origin rpy="0 -1.57079632679 0" xyz="0.005 0 0"/>
      <geometry>
        <cylinder length="0.01" radius="0.02"/>
      </geometry>
    </collision>
  </link>
  <joint name="phi_2" type="continuous">
    <parent link="lower_leg_attach_link_2"/>
    <child link="lower_leg_prespring_2"/>
    <origin rpy="0 0 1.57079632679" xyz="0 -0.09 0"/>
    <axis rpy="0 0 0" xyz="-1 0 0"/>
    <dynamics damping="0.0" friction="0.0"/>
  </joint>
  <!-- define a frame at the knee between the lower and upper legs -->
  <link name="knee_2">
    <!--    <origin xyz="${0 if axis == 'z' else h/2.0} 0 ${h/2.0 if axis == 'z' else 0}" rpy="0 ${0 if axis == 'z' else -pi/2.0} 0" />-->
    <inertial>
      <mass value="1e-05"/>
      <!-- shift the origin to the center of the link from the end. how this is done depends on if
      the cylinder is x aligned or z aligned-->
      <origin rpy="0 0 0" xyz="5e-11 0 0"/>
      <inertia ixx="5e-26" ixy="0" ixz="0" iyy="3.33333333333e-26" iyz="0" izz="3.33333333333e-26"/>
    </inertial>
  </link>
  <!-- define the universal joint between he upper and lower links -->
  <!-- This is the knee pitch angle joint -->
  <joint name="beta_2" type="continuous">
    <parent link="lower_leg_2"/>
    <child link="knee_2"/>
    <origin rpy="0 0 0" xyz="0.2 0 0"/>
    <axis rpy="0 0 0" xyz="0 -1 0"/>
    <dynamics damping="0.0" friction="0.0"/>
  </joint>
  <link name="upper_leg_2">
    <visual>
      <!-- shift the visual so that the link frame is at one end of the cylinder, and
           rotate it so that it matches the proper axis alignment -->
      <origin rpy="0 -1.57079632679 0" xyz="0.184 0 0"/>
      <geometry>
        <cylinder length="0.368" radius="0.009"/>
      </geometry>
      <material name="dark_pink"/>
    </visual>
    <!--    <origin xyz="${0 if axis == 'z' else h/2.0} 0 ${h/2.0 if axis == 'z' else 0}" rpy="0 ${0 if axis == 'z' else -pi/2.0} 0" />-->
    <inertial>
      <mass value="1"/>
      <!-- shift the origin to the center of the link from the end. how this is done depends on if
      the cylinder is x aligned or z aligned-->
      <origin rpy="0 0 0" xyz="0.184 0 0"/>
      <inertia ixx="4.05e-05" ixy="0" ixz="0" iyy="0.0113055833333" iyz="0" izz="0.0113055833333"/>
    </inertial>
    <collision>
      <origin rpy="0 -1.57079632679 0" xyz="0.184 0 0"/>
      <geometry>
        <cylinder length="0.368" radius="0.009"/>
      </geometry>
    </collision>
  </link>
  <!-- this is the knee yaw angle joint -->
  <joint name="gamma_2" type="continuous">
    <parent link="knee_2"/>
    <child link="upper_leg_2"/>
    <axis rpy="0 0 0" xyz="0 0 -1"/>
    <dynamics damping="0.0" friction="0.0"/>
  </joint>
  <!-- This link and fixed joint is used as a placeholder for where the lower leg attaches to the base -->
  <link name="lower_leg_attach_link_3">
    <!--    <origin xyz="${0 if axis == 'z' else h/2.0} 0 ${h/2.0 if axis == 'z' else 0}" rpy="0 ${0 if axis == 'z' else -pi/2.0} 0" />-->
    <inertial>
      <mass value="1e-05"/>
      <!-- shift the origin to the center of the link from the end. how this is done depends on if
      the cylinder is x aligned or z aligned-->
      <origin rpy="0 0 0" xyz="5e-11 0 0"/>
      <inertia ixx="5e-26" ixy="0" ixz="0" iyy="3.33333333333e-26" iyz="0" izz="3.33333333333e-26"/>
    </inertial>
  </link>
  <joint name="lower_leg_attach_joint_3" type="fixed">
    <parent link="world"/>
    <child link="lower_leg_attach_link_3"/>
    <origin rpy="0 0 4.18879020479" xyz="-0.09 -0.155884572681 0"/>
    <dynamics damping="0.0" friction="0.0"/>
  </joint>
  <link name="lower_leg_3">
    <visual>
      <!-- shift the visual so that the link frame is at one end of the cylinder, and
           rotate it so that it matches the proper axis alignment -->
      <origin rpy="0 -1.57079632679 0" xyz="0.1 0 0"/>
      <geometry>
        <cylinder length="0.2" radius="0.009"/>
      </geometry>
      <material name="light_pink"/>
    </visual>
    <!--    <origin xyz="${0 if axis == 'z' else h/2.0} 0 ${h/2.0 if axis == 'z' else 0}" rpy="0 ${0 if axis == 'z' else -pi/2.0} 0" />-->
    <inertial>
      <mass value="1"/>
      <!-- shift the origin to the center of the link from the end. how this is done depends on if
      the cylinder is x aligned or z aligned-->
      <origin rpy="0 0 0" xyz="0.1 0 0"/>
      <inertia ixx="4.05e-05" ixy="0" ixz="0" iyy="0.00335358333333" iyz="0" izz="0.00335358333333"/>
    </inertial>
    <collision>
      <origin rpy="0 -1.57079632679 0" xyz="0.1 0 0"/>
      <geometry>
        <cylinder length="0.2" radius="0.009"/>
      </geometry>
    </collision>
  </link>
  <!-- connect the lower leg to the base -->
  <!-- this is the after the spring angle joint -->
  <joint name="theta_3" type="revolute">
    <parent link="lower_leg_attach_link_3"/>
    <child link="lower_leg_3"/>
    <origin rpy="0 0 0" xyz="0 0 0"/>
    <axis rpy="0 0 0" xyz="0 -1 0"/>
    <limit effort="100" lower="-0.785398163397" upper="1.57079632679" velocity="100"/>
    <dynamics damping="0.0" friction="0.0"/>
  </joint>
  <link name="lower_leg_prespring_3">
    <visual>
      <!-- shift the visual so that the link frame is at one end of the cylinder, and
           rotate it so that it matches the proper axis alignment -->
      <origin rpy="0 -1.57079632679 0" xyz="0.005 0 0"/>
      <geometry>
        <cylinder length="0.01" radius="0.02"/>
      </geometry>
      <material name="prespring_color"/>
    </visual>
    <!--    <origin xyz="${0 if axis == 'z' else h/2.0} 0 ${h/2.0 if axis == 'z' else 0}" rpy="0 ${0 if axis == 'z' else -pi/2.0} 0" />-->
    <inertial>
      <mass value="1"/>
      <!-- shift the origin to the center of the link from the end. how this is done depends on if
      the cylinder is x aligned or z aligned-->
      <origin rpy="0 0 0" xyz="0.005 0 0"/>
      <inertia ixx="0.0002" ixy="0" ixz="0" iyy="0.000108333333333" iyz="0" izz="0.000108333333333"/>
    </inertial>
    <collision>
      <origin rpy="0 -1.57079632679 0" xyz="0.005 0 0"/>
      <geometry>
        <cylinder length="0.01" radius="0.02"/>
      </geometry>
    </collision>
  </link>
  <joint name="phi_3" type="continuous">
    <parent link="lower_leg_attach_link_3"/>
    <child link="lower_leg_prespring_3"/>
    <origin rpy="0 0 1.57079632679" xyz="0 -0.09 0"/>
    <axis rpy="0 0 0" xyz="-1 0 0"/>
    <dynamics damping="0.0" friction="0.0"/>
  </joint>
  <!-- define a frame at the knee between the lower and upper legs -->
  <link name="knee_3">
    <!--    <origin xyz="${0 if axis == 'z' else h/2.0} 0 ${h/2.0 if axis == 'z' else 0}" rpy="0 ${0 if axis == 'z' else -pi/2.0} 0" />-->
    <inertial>
      <mass value="1e-05"/>
      <!-- shift the origin to the center of the link from the end. how this is done depends on if
      the cylinder is x aligned or z aligned-->
      <origin rpy="0 0 0" xyz="5e-11 0 0"/>
      <inertia ixx="5e-26" ixy="0" ixz="0" iyy="3.33333333333e-26" iyz="0" izz="3.33333333333e-26"/>
    </inertial>
  </link>
  <!-- define the universal joint between he upper and lower links -->
  <!-- This is the knee pitch angle joint -->
  <joint name="beta_3" type="continuous">
    <parent link="lower_leg_3"/>
    <child link="knee_3"/>
    <origin rpy="0 0 0" xyz="0.2 0 0"/>
    <axis rpy="0 0 0" xyz="0 -1 0"/>
    <dynamics damping="0.0" friction="0.0"/>
  </joint>
  <link name="upper_leg_3">
    <visual>
      <!-- shift the visual so that the link frame is at one end of the cylinder, and
           rotate it so that it matches the proper axis alignment -->
      <origin rpy="0 -1.57079632679 0" xyz="0.184 0 0"/>
      <geometry>
        <cylinder length="0.368" radius="0.009"/>
      </geometry>
      <material name="dark_pink"/>
    </visual>
    <!--    <origin xyz="${0 if axis == 'z' else h/2.0} 0 ${h/2.0 if axis == 'z' else 0}" rpy="0 ${0 if axis == 'z' else -pi/2.0} 0" />-->
    <inertial>
      <mass value="1"/>
      <!-- shift the origin to the center of the link from the end. how this is done depends on if
      the cylinder is x aligned or z aligned-->
      <origin rpy="0 0 0" xyz="0.184 0 0"/>
      <inertia ixx="4.05e-05" ixy="0" ixz="0" iyy="0.0113055833333" iyz="0" izz="0.0113055833333"/>
    </inertial>
    <collision>
      <origin rpy="0 -1.57079632679 0" xyz="0.184 0 0"/>
      <geometry>
        <cylinder length="0.368" radius="0.009"/>
      </geometry>
    </collision>
  </link>
  <!-- this is the knee yaw angle joint -->
  <joint name="gamma_3" type="continuous">
    <parent link="knee_3"/>
    <child link="upper_leg_3"/>
    <axis rpy="0 0 0" xyz="0 0 -1"/>
    <dynamics damping="0.0" friction="0.0"/>
  </joint>
</robot>
